<?xml version='1.0'?>
<sdf version='1.6'>
  <model name='rover'>
    <link name='base_link'>
      <pose>0 0 0.2 0 0 0</pose>
      <inertial>
        <mass>5.0</mass>
        <inertia>
          <ixx>0.08</ixx>
          <ixy>0</ixy>
          <ixz>0</ixz>
          <iyy>0.1</iyy>
          <iyz>0</iyz>
          <izz>0.1</izz>
        </inertia>
      </inertial>
      <collision name='collision'>
        <geometry>
          <box><size>0.5 0.3 0.1</size></box>
        </geometry>
      </collision>
      <visual name='visual'>
        <geometry>
          <box><size>0.5 0.3 0.1</size></box>
        </geometry>
      </visual>
      <sensor name='imu_sensor' type='imu'>
        <always_on>1</always_on>
        <update_rate>100</update_rate>
      </sensor>
    </link>

    <!-- Wheels -->
    <link name='left_wheel'>
      <pose>0.15 0.17 0.1 0 1.5707 0</pose>
      <inertial><mass>0.5</mass><inertia><ixx>0.001</ixx><iyy>0.001</iyy><izz>0.002</izz></inertia></inertial>
      <collision name='collision'><geometry><cylinder><radius>0.1</radius><length>0.05</length></cylinder></geometry></collision>
      <visual name='visual'><geometry><cylinder><radius>0.1</radius><length>0.05</length></cylinder></geometry></visual>
    </link>
    <link name='right_wheel'>
      <pose>0.15 -0.17 0.1 0 1.5707 0</pose>
      <inertial><mass>0.5</mass><inertia><ixx>0.001</ixx><iyy>0.001</iyy><izz>0.002</izz></inertia></inertial>
      <collision name='collision'><geometry><cylinder><radius>0.1</radius><length>0.05</length></cylinder></geometry></collision>
      <visual name='visual'><geometry><cylinder><radius>0.1</radius><length>0.05</length></cylinder></geometry></visual>
    </link>
    <link name='caster_wheel'>
        <pose>-0.15 0 0.05 0 0 0</pose>
        <inertial><mass>0.2</mass><inertia><ixx>0.0001</ixx><ixy>0</ixy><ixz>0</ixz><iyy>0.0001</iyy><iyz>0</iyz><izz>0.0001</izz></inertia></inertial>
        <collision name='collision'><geometry><sphere><radius>0.05</radius></sphere></geometry></collision>
        <visual name='visual'><geometry><sphere><radius>0.05</radius></sphere></geometry></visual>
    </link>

    <!-- Joints -->
    <joint name='left_wheel_joint' type='revolute'><parent>base_link</parent><child>left_wheel</child><axis><xyz>0 1 0</xyz></axis></joint>
    <joint name='right_wheel_joint' type='revolute'><parent>base_link</parent><child>right_wheel</child><axis><xyz>0 1 0</xyz></axis></joint>
    <joint name='caster_wheel_joint' type='ball'><parent>base_link</parent><child>caster_wheel</child></joint>

    <!-- ArduPilot Plugin -->
    <plugin name='ardupilot_plugin' filename='libArduPilotPlugin.so'>
      <modelName>rover</modelName>
      <imuName>imu_sensor</imuName>
      <control>
        <motor>
            <jointName>left_wheel_joint</jointName>
            <motorType>throttle</motorType>
            <motorChannel>1</motorChannel>
        </motor>
        <motor>
            <jointName>right_wheel_joint</jointName>
            <motorType>throttle</motorType>
            <motorChannel>3</motorChannel>
        </motor>
      </control>
    </plugin>
  </model>
</sdf>
